Workbook

Sheet IMAGEN

Sheet Ficha de costo (Resumen)
A1: MINISTERIO DE FINANZAS Y PRECIOS FICHA PARA PRECIOS O TARIFAS
A4: EMPRESA:
A5: ORGANISMO: | J5: 900 | K5: 2100
A6: Producto o Servicio: Ficha de Puerta 900x2100 c cristal parsol traslusido | C6: Plan de produccion:
A7: Código: | C7: % utilización capacidad:
A8: Unidad de Medida:U | C8: Produccion Periodo Ant:
A9: Precio de Venta Total: | C9: % Margen de Utilidad:
A10: CONCEPTOS | B10: Fila | C10: Total Unitario:
A11: (1) | B11: (2) | C11: (3)
A12: MATERIAS PRIMAS Y MATERIALES | B12: 1 | C12: =SUM(C13:C16) -> 62686.756
A13: Insumos | B13: 1.1 | C13: ='Consumo Material'!F49 -> 62686.59
A14: Combustibles | B14: 1.2 | C14: ='Consumo Material'!F39 -> 0
A15: Energía | B15: 1.3 | C15: ='Consumo Material'!F40 -> 0.16650777
A16: Agua | B16: PERFIL ALUMINIO - TRAVESAÑO INTERMEDIO | C16: ='Consumo Material'!F41 -> 0 | D16: 5.8 | G16: 32.74
A17: SALARIOS | B17: 2 | C17: ='Salarios Directos '!E34+'Salarios Directos '!E1*9.09% -> 1382.8125
A18: Estimulación | B18: 2.1 | C18: ='Salarios Directos '!E14 -> 0 | D18: 4
A19: Otros Gastos Directos | B19: 3 | C19: ='Otros Gastos Directos '!B13 -> 7056.8513 | D19: 16
A20: Gastos asociados a la Producción | B20: 4 | C20: ='Coeficientes(Gastos Indirectos)'!C8 -> 843.51563
A21: De ello: Salarios | B21: 4.1 | C21: ='Coeficientes(Gastos Indirectos)'!C12 -> 69.140625 | D21: 5.5
A22: Combustibles | B22: 4.2 | C22: ='Coeficientes(Gastos Indirectos)'!C10 -> 96.796875 | D22: 16.3
A23: COSTO TOTAL ( 1+2+3+4 ) | B23: 5 | C23: =SUM(C12,C17,C19,C20, ) -> 71969.936 | D23: 10.8
A24: Gastos Generales y de Administración | B24: 6 | C24: ='Coeficientes(Gastos Indirectos)'!C26 -> 497.8125
A25: De ello: Salarios | B25: 6.1 | C25: ='Coeficientes(Gastos Indirectos)'!C30 -> 55.3125
A26: Combustibles | B26: 6.2 | C26: ='Coeficientes(Gastos Indirectos)'!C28 -> 110.625 | D26: 12
A27: Gastos de Distribución y Venta | B27: 7 | C27: ='Coeficientes(Gastos Indirectos)'!C17 -> 41.484375 | G27: 16.73
A28: Salarios | B28: 7.1 | C28: ='Coeficientes(Gastos Indirectos)'!C30 -> 55.3125
A29: Combustibles | B29: 7.2 | C29: ='Coeficientes(Gastos Indirectos)'!C28 -> 110.625
A30: Gastos Financieros | B30: 8 | C30: ='Gastos Financieros '!D29 -> 0 | D30: =(0.72*1.3)*1.1 -> 1.0296 | G30: 9.65 | J30: 440
A31: Gastos por Financiamiento entregado a la OSDE 840 | B31: SANWICH | C31: 0 | D31: =(0.72*0.61) -> 0.4392
A32: Contribución a la Seguridad Social | B32: 10 | C32: =(C17+C21+C25+C28)*12.5% -> 195.32227
A33: Gastos de Seguridad Social a corto plazo | B33: 11 | C33: =(C17+C21+C25+C28)*1.5% -> 23.438672
A34: Impuesto por la Utiliz. de la Fuerza de Trabajo | B34: 12 | C34: =(C17+C21+C25+C28)*5% -> 78.128906
A35: Impuesto Especial a Productos | B35: 15 | C35: 0
A36: Otros gastos autorizados por el MFP | B36: 16 | C36: 0
A37: TOTAL DE GASTOS ( suma de la 6 a la 16 ) | B37: 17 | C37: =C24+C27+C30+C31+C32+C33+C34+C35+C36 -> 836.18672 | F37: m2
A38: TOTAL DE COSTOS Y GASTOS | B38: 44213 | C38: =C23+C37 -> 72806.123 | D38: COSTO USD | E38: =C38/120 -> 606.71769 | F38: =E38/F41 -> 116.49725
A39: Normativa de Utilidad a aplicar | B39: 18 | C39: 50
A40: Masa de Utilidad ( 5 x 18 / 100 ) | B40: 19 | C40: =(C23*C39)/100 -> 35984.968 | F40: m2 | G40: M2 Precio
A41: P R E C I O ó T A R I F A ( 5 + 17 + 19 ) | B41: 20 | C41: =C23+C37+C40 -> 108791.09 | D41: PRECIO USD | E41: =C41/120 -> 906.59242 | F41: ='Consumo Material'!J6*'Consumo Material'!K6 -> 5.208 | G41: =E41/F41 -> 174.07689 | H41: 6% Arrendamiento
A42: PRECIO CON Arendamiento 6% | B42: 21 | C42: =C41/0.94 -> 115735.2 | H42: =C42-C41 -> 6944.1122
...

Sheet Consumo Material
A2: DESAGREGACION DE LOS INSUMOS
A4: ORGANISMO/EMPRESA: | J4: Ancho | K4: Alto
A5: CODIGO DEL PRODUCTO O SERVICIO: | J5: 2480 | K5: 2100
J6: =J5/1000 -> 2.48 | K6: =K5/1000 -> 2.1
A7: UNIDAD DE MEDIDA: CANTIDADES FISICAS: | K7: =J6*K6 -> 5.208
A8: Codigo | B8: Descripción | C8: UM | D8: COSTO PROPUESTO
D9: TOTAL
D10: Norma de consumo | E10: Precio | F10: Importe MN
A11: 1 | B11: 2 | C11: 3 | D11: 9 | E11: 11 (9x10) | F11: 13(9x12)
B12: MATERIAS PRIMAS Y MATERIALES PRINCIPALES | G12: USD | H12: X120 | I12: metro usd | J12: X120
A13: SP40-01 | B13: PERFIL ALUMINIO - MARCO PARA BATIENTE-PAÑO FIJO | C13: M | D13: 7.2 | E13: =J13 -> 448.96552 | F13: =D13*E13 -> 3232.5517 | G13: 21.7 | H13: =G13*120 -> 2604 | I13: =G13/5.8 -> 3.7413793 | J13: =I13*120 -> 448.96552
A14: SP40-02 | B14: PERFIL ALUMINIO - HOJA PARA PUERTA BATIENTE INTERIOR-EXTERIOR | C14: M | D14: 11.6 | E14: =J14 -> 798.62069 | F14: =D14*E14 -> 9264 | G14: 38.6 | H14: =G14*120 -> 4632 | I14: =G14/5.8 -> 6.6551724 | J14: =I14*120 -> 798.62069
A15: SP40-12 | B15: REVESTIMIENTO-TABLILLA (7 X 114) mm | C15: M | D15: 34.8 | E15: =J15 -> 702.62069 | F15: =D15*E15 -> 24451.2 | G15: 33.96 | H15: =G15*120 -> 4075.2 | I15: =G15/5.8 -> 5.8551724 | J15: =I15*120 -> 702.62069
B16: INVERSOR CENTRAL | C16: M | D16: 2.06 | E16: =J16 -> 552.41379 | F16: =D16*E16 -> 1137.9724 | G16: 26.7 | H16: =G16*120 -> 3204 | I16: =G16/5.8 -> 4.6034483 | J16: =I16*120 -> 552.41379
A17: SP40-04 | B17: PERFIL ALUMINIO - TRAVESAÑO INTERMEDIO ZOCALO | C17: M | D17: 6.9 | E17: =J17 -> 852.41379 | F17: =D17*E17 -> 5881.6552 | G17: 41.2 | H17: =G17*120 -> 4944 | I17: =G17/5.8 -> 7.1034483 | J17: =I17*120 -> 852.41379
B18: ACCESORIOS | F18: =D18*E18 -> 0 | M18: mlc | N18: x120 | P18: Cont aluminio | R18: x120
A19: HIN-61 | B19: BISAGRA DE PUERTAS DE DOS PATAS | C19: U | D19: 10 | E19: =H19 -> 362.4 | F19: =D19*E19 -> 3624 | G19: 3.02 | H19: =G19*120 -> 362.4 | K19: 1250 mlc aranceles | M19: 1250 | N19: =M19*120 -> 150000 | P19: alumini | Q19: 59290.77 | R19: =Q19*120 -> 7114892.4
A20: SCW-04 | B20: TORNILLO ACERO CABEZA ALLEN 5 MM AUTO ROSCA-Ø (4.8 X 55) mm | C20: U | D20: 24 | E20: =H20 -> 7.2 | F20: =D20*E20 -> 172.8 | G20: 0.06 | H20: =G20*120 -> 7.2 | K20: 707,721 cup aranceles | N20: 707721 | P20: accesorios | Q20: 25879.94 | R20: =Q20*120 -> 3105592.8
A21: SCW-06 | B21: TORNILLO ACERO CABEZA AVELLANADA PH2 CON TACO DE PVC-(Ø 8 X 80) mm | C21: U | D21: 0 | E21: =H21 -> 27.6 | F21: =D21*E21 -> 0 | G21: 0.23 | H21: =G21*120 -> 27.6 | J21: 120000 | K21: 120,000 cup de trasporte | N21: =N19+N20 -> 857721 | R21: =R19+R20 -> 10220485
A22: SEA-29 | B22: EPDM BURLETE-SELLO-HOJA BATIENTE | C22: M | D22: 11.5 | E22: =H22 -> 45.6 | F22: =D22*E22 -> 524.4 | G22: 0.38 | H22: =G22*120 -> 45.6 | K22: 1 | N22: =N21+120000 -> 977721
A23: SEA-80 | B23: EPDM BURLETE-SELLO-MARCO Y ACRISTALAMIENTO | C23: M | D23: 22.15 | E23: =H23 -> 45.6 | F23: =D23*E23 -> 1010.04 | G23: 0.38 | H23: =G23*120 -> 45.6 | P23: x100 | S23: Gasto Total
A24: SEA-54 | B24: EPDM BURLETE-SELLO-HOJA BATIENTE | C24: M | D24: 16.15 | E24: =H24 -> 45.6 | F24: =D24*E24 -> 736.44 | G24: 0.38 | H24: =G24*120 -> 45.6 | L24: Aranceles sin transporte | O24: =N21/R21 -> 0.08392175 | P24: =O24*100 -> 8.392175 | Q24: Gasto materiales+transporte +aranceles | S24: =R21+N22 -> 11198206 | U24: 1
A25: BRA-38 | B25: ESCUADRA UNION 45° ALUMINIO - (35.9 X37.3) mm | C25: U | D25: 4 | E25: =H25 -> 63.6 | F25: =D25*E25 -> 254.4 | G25: 0.53 | H25: =G25*120 -> 63.6 | J25: Esc Hoja | P25: % | Q25: Gasto Aranceles y transporte | S25: =N22 -> 977721 | U25: X
A26: BRA-13 | B26: ESCUADRA UNION 45° ALUMINIO - (35.9 X13.9) mm | C26: U | D26: 2 | E26: =H26 -> 44.4 | F26: =D26*E26 -> 88.8 | G26: 0.37 | H26: =G26*120 -> 44.4 | J26: Esc Marco | L26: Aranceles mas transporte | O26: =N22/R21 -> 0.095662875 | P26: =O26*100 -> 9.5662875 | Q26: %Aranceles y transporte | T26: =S25/S24 -> 0.087310502
A27: PLU-100 | B27: TAPON ORIFICIO PVC - Ø12 mm-BLANCO | C27: U | D27: 24 | E27: =H27 -> 4.8 | F27: =D27*E27 -> 115.2 | G27: 0.04 | H27: =G27*120 -> 4.8
A28: LOK-51 | B28: CERRADURA VERTICAL ALUMINIO PARA PUERTA BATIENTE - CON CILINDRO-3 LLAVES-BLANCO | C28: U | D28: 1 | E28: =H28 -> 1896 | F28: =D28*E28 -> 1896 | G28: 15.8 | H28: =G28*120 -> 1896
B29: PESTILLO DESLIZABLE ALUMINIO EN CAMARA DE PERFIL CON SU BASE ALUMINIO-BLANCO | C29: U | D29: 2 | E29: =H29 -> 204 | F29: =D29*E29 -> 408 | G29: 1.7 | H29: =G29*120 -> 204 | M29: cont vidrio | N29: 20243.57 | O29: =120*N29 -> 2429228.4 | R29: %Aranceles | T29: =N21/S24 -> 0.0765945
B30: TORNILLO ROSCA CHAPA 4.2 X 13 | C30: U | D30: 6 | E30: =H30 -> 0 | F30: =D30*E30 -> 0 | H30: =G30*120 -> 0 | R30: %Transportacion | T30: =J21/S24 -> 0.010716002
A31: 7005.29.00 | B31: CRISTAL PLANO TRANSLUCIDO PARSOL BRONCE OSCURO | C31: M2 | D31: 0 | E31: =H31 -> 1728 | F31: =D31*E31 -> 0 | G31: 14.4 | H31: =G31*120 -> 1728 | J31: 440
B32: MELAMINA | C32: M2 | D32: 0 | H32: 2857.14 | I32: =H32*D32 -> 0 | J32: =I32/J31 -> 0 | K32: USD
B33: SANWISH | C33: M2 | D33: 0 | G33: 12.6 | H33: =D33*G33 -> 0 | K33: =H33+J32 -> 0
H34: =G34*120 -> 0
G35: usd | I35: USD | J35: m2 | K35: 1m2
B36: Sub Total Materias Primas | E36: =SUM(E12:E34) -> 7829.8345 | F36: =SUM(F12:F34) -> 52797.459 | G36: df | I36: =F36/120 -> 439.97883 | J36: =J6*K6 -> 5.208 | K36: =I36/J36 -> 84.481342
B38: Gastos de tranferencia financiera en el exterior | C38: % | D38: 0.1 | F38: =F36*0.1 -> 5279.7459 | K38: MELAMINA
B39: Diesel Combustible Regular | C39: t | E39: =D39 -> 0 | F39: =D3*E39 -> 0 | K39: 1.15 | L39: 4166.67 | M39: =K39*L39 -> 4791.6705
B40: Energía Eléctrica | C40: Mwh | D40: 4.29e-05 | E40: 3881.3 | F40: =D40*E40 -> 0.16650777 | K40: 0
B41: Agua | C41: 50 | D41: 0 | E41: 10.85 | F41: =D5*E41 -> 0 | I41: x 8.73%
B42: Aranceles de importacion del contenedor (707721 cup+1250mlc) | C42: % | D42: =T29 -> 0.0765945 | E42: =T26 -> 0.087310502 | F42: =I42-F36 -> 4609.2182 | I42: =F36*1.0873 -> 57406.678
B43: Gastos Transportacion Contenedor | C43: % | D43: =T30 -> 0.010716002
...

Sheet Salarios Directos 
A1: MODELO 3 - DESGLOSE DE LOS GASTOS DE SALARIO DE LOS OBREROS DE LA PRODUCCIÓN Y LOS SERVICIOS
A4: ORGANISMO: MINDUS | C4: DESCRIPCION DEL PRODUCTO O SERVICIO:
J5: 900 | K5: 2100
A6: PRECIO:
A7: MN:__X________ DIVISA:_________ | C7: UM T
A8: VOLUMEN DE PRODUCCION: | C8: CODIGO:
C10: Importe de los gastos
A11: Concepto del gasto de salario | B11: Fila | C11: M. N. | D11: Divisas | E11: Total
A13: Salario fijo | B13: 01 | C13: ='Desglose Salario'!J29 -> 1382.8125 | E13: =C13 -> 1382.8125
A14: Salario movil | B14: 02 | C14: 0 | E14: =C14 -> 0
B16: PERFIL ALUMINIO - TRAVESAÑO INTERMEDIO | D16: 5.8 | G16: 32.74
D18: 4
D19: 16
D21: 5.5
D22: 16.3
D23: 10.8
D26: 12
G27: 16.73
D30: =(0.72*1.3)*1.1 -> 1.0296 | G30: 9.65 | J30: 440
B31: SANWICH | D31: =(0.72*0.61) -> 0.4392
A34: Total | B34: 03 | C34: =SUM(C13:C14) -> 1382.8125 | E34: =SUM(E13:E14) -> 1382.8125
A36: Confeccionado por : | C36: Firma: | D36: Cargo: | E36: Fecha:
A38: Aprobado por : | C38: Firma: | D38: Cargo: | E38: Fecha:
D43: =IF(C39>0, ((C43/120)+'Consumo Material'!J32)*103%, (C43/120)+'Consumo Material'!J32) -> 0 | E43: =D43*0.1 -> 0 | F43: =SUM(D43:E43) -> 0

Sheet Coeficientes(Gastos Indirectos)
A1: MODELO 4 - PROPUESTA DE COEFICIENTES DE GASTOS INDIRECTOS DE PRODUCCIÓN, DISTRIBUCIÓN Y VENTAS Y GENERALES Y DE ADMINISTRACIÓN
A3: ORGANISMO:
A4: Empresa de Antenas
A6: Concepto de gastos | B6: Fila | C6: Importe de los gastos
C7: M. N. | D7: 76203.84
A8: Gastos indirectos de producción (731) | B8: 01 | C8: =C9+C10+C11+C12+C13+C14+C15+C16 -> 843.51563 | D8: 0.1736
A9: Materias primas y materiales | B9: 02 | C9: =$C$37*0.19 -> 262.73438 | D9: 0.0342 | E9: =C9/C37 -> 0.19
A10: Combustible | B10: 03 | C10: =$C$37*0.07 -> 96.796875 | D10: 0.0046 | E10: =C10/C37 -> 0.07
A11: Energía | B11: 04 | C11: =$C$37*0.13 -> 179.76563 | D11: 0.0148 | E11: =C11/C37 -> 0.13
A12: Salarios | B12: 05 | C12: =$C$37*0.05 -> 69.140625 | D12: 0.0911 | E12: =C12/C37 -> 0.05
A13: Otros gastos de la fuerza de trabajo | B13: 06 | C13: =$C$37*0.02 -> 27.65625 | D13: 0.0003 | E13: =C13/C37 -> 0.02
A14: Depreciación | B14: 07 | C14: =$C$37*0.03 -> 41.484375 | D14: 0.0089 | E14: =C14/C37 -> 0.03
A15: Arrendamiento de Equipos | B15: 08 | C15: =$C$37*0 -> 0 | D15: 0.0003 | E15: =C15/C37 -> 0
A16: Mantenimiento y reparación | C16: =$C$37*0.12 -> 165.9375 | D16: 0.0194 | E16: =C16/C37 -> 0.12
A17: Gastos de distribución y ventas (821) | B17: 11 | C17: =C18+C19+C20++C21+C22+C23+C24 -> 41.484375 | D17: 0.060033513
A18: Materias primas y materiales | B18: 12 | C18: =$C$37*0 -> 0
A19: Combustible | B19: 13 | C19: =$C$37*0 -> 0 | D19: 0.0007
A20: Energía | B20: 14 | C20: =$C$37*0.03 -> 41.484375 | D20: 0.0023
A21: Salarios | B21: 15 | C21: =$C$37*0 -> 0 | D21: 0.057
A22: Otros gastos de la fuerza de trabajo | B22: 16 | C22: =$C$37*0 -> 0
A23: Depreciación | B23: 17 | C23: =$C$37*0 -> 0 | D23: 0.0001
A24: Otros gastos monetarios | B24: 18 | C24: =$C$37*0 -> 0
A26: Gastos generales y de administración (822) | B26: 21 | C26: =C27+C28+C29+C30+C31+C32+C33+C34 -> 497.8125 | D26: 0.7664
A27: Materias primas y materiales | B27: 22 | C27: =$C$37*0.1 -> 138.28125
A28: Combustible | B28: 23 | C28: =$C$37*0.08 -> 110.625 | D28: 0.0001
A29: Energía Eléctrica | B29: 24 | C29: =$C$37*0.09 -> 124.45313 | D29: 0.0114
A30: Salarios | B30: 25 | C30: =$C$37*0.04 -> 55.3125 | D30: 0.2551
A31: Otros gastos de la fuerza de trabajo | B31: 26 | C31: =$C$37*0.02 -> 27.65625
A32: Depreciación | B32: 27 | C32: =$C$37*0.03 -> 41.484375 | D32: 0.023
A33: Otros gastos monetarios | B33: 28 | C33: =$C$37*0 -> 0 | D33: 0.4761
A34: Alimentos | B34: 29 | C34: 0 | D34: 0.0007
A35: Total | B35: 30 | C35: =C8+C17+C26 -> 1382.8125 | D35: 1
A37: Salario básico de los trabajadores directos a la producción | B37: 31 | C37: ='Desglose Salario'!J29 -> 1382.8125
E38: Coeficiente de gastos Indirectos Aprobados Resolución 362/2014 MFP
A39: Coeficiente de gastos indirectos de producción | B39: 32 | C39: =C8/C37 -> 0.61
A40: Coeficiente de gastos de distribución y ventas | B40: 33 | C40: =C17/C37 -> 0.03
A41: Coeficiente de gastos generales y de administración | B41: 34 | C41: =C26/C37 -> 0.36
C42: =SUM(C39:C41) -> 1 | F42: 1
A43: Confeccionado por : | C43: Cargo:
A45: Aprobado por : | C45: Cargo:

Sheet Desglose Salario
A1: DESGLOSE DEL GASTO DE “SALARIO DE LOS OBREROS DE LA PRODUCCION Y LOS SERVICIOS” | H1: Ministerio de Finanzas y Precios
A4: Empresa: | E4: Organismo /
A5: Código del producto o servicio: CANTIDADES FISICAS:
A6: Descripción del Producto o Servicio:
A8: Unidad de valor: pesos y centavos. Unidad de tiempo: Hora.
A9: Descripción de las operaciones | C9: Cantidad de trabajadores por operación o actividad | D9: Categoría Ocupacional | E9: Grupo Escala | F9: Salario/hora según Categoría y Grupo | G9: Pagos Adicionales por hora | I9: Norma de tiempo (en horas) | J9: Gasto de Salario
A10: 1 | B10: 2 | C10: 2 | D10: 3 | E10: 4 | F10: 5 | G10: 6 | I10: 7 | J10: 8
A11: CORTE Acarreo y Prep Produccion | B11: Operario “A” de Equipos Electrónicos y Estructuras (J. Brigada) | C11: 1 | D11: O | F11: 156.25 | H11: =A11*(D11+E11)*G11 -> #VALUE! | I11: 0.15 | J11: =C11*(F11+G11)*I11 -> 23.4375
B12: Operario “A” de Equipos Electrónicos y Estructuras | C12: 1 | D12: O | F12: 104.16667 | H12: =A12*(D12+E12)*G12 -> #VALUE! | I12: 0.15 | J12: =C12*(F12+G12)*I12 -> 15.625
A13: TROQUELADO | B13: Operario “A” de Equipos Electrónicos y Estructuras | C13: 1 | D13: O | F13: 104.16667 | H13: =A13*(D13+E13)*G13 -> #VALUE! | I13: 0.15 | J13: =C13*(F13+G13)*I13 -> 15.625 | O13: Salario Mensual
A14: CALADO | B14: Operario “A” de Equipos Electrónicos y Estructuras | C14: 1 | D14: O | F14: 156.25 | H14: =A14*(D14+E14)*G14 -> #VALUE! | I14: 0.5 | J14: =C14*(F14+G14)*I14 -> 78.125 | O14: 20000 | P14: 30000 | Q14: 15000 | R14: 50000 | S14: 10000 | T14: 6500
A15: C. DE CUBIERTA | B15: Operario Cristalero | C15: 1 | D15: O | F15: 78.125 | H15: =A15*(D15+E15)*G15 -> #VALUE! | I15: 0.5 | J15: =C15*(F15+G15)*I15 -> 39.0625 | N15: Dias | O15: 24 | P15: 24 | Q15: 24 | R15: 24 | S15: 24 | T15: 24
A16: ENSAMBLE | B16: Operario “A” de Equipos Electrónicos y Estructuras (J. Brigada) | C16: 1 | D16: O | F16: 156.25 | H16: =A16*(D16+E16)*G16 -> #VALUE! | I16: 1.05 | J16: =C16*(F16+G16)*I16 -> 164.0625 | N16: Horas | O16: =O15*8 -> 192 | P16: =P15*8 -> 192 | Q16: =Q15*8 -> 192 | R16: =R15*8 -> 192 | S16: =S15*8 -> 192 | T16: =T15*8 -> 192
B17: Operario “A” de Equipos Electrónicos y Estructuras | C17: 2 | D17: O | F17: 104.16667 | H17: =A17*(D17+E17)*G17 -> #VALUE! | I17: 1.05 | J17: =C17*(F17+G17)*I17 -> 218.75 | N17: SalxHora | O17: =O14/O16 -> 104.16667 | P17: =P14/P16 -> 156.25 | Q17: =Q14/Q16 -> 78.125 | R17: =R14/R16 -> 260.41667 | S17: =S14/S16 -> 52.083333 | T17: =T14/T16 -> 33.854167
A18: Calculos Tecnicos | B18: Tecnicos Dir | C18: 2 | D18: T | F18: 260.41667 | I18: 1 | J18: =C18*(F18+G18)*I18 -> 520.83333
B19: Pantrista | C19: 1 | D19: O | F19: 52.083333 | I19: 2 | J19: =C19*(F19+G19)*I19 -> 104.16667
B20: Custodios | C20: 3 | D20: O | F20: 33.854167 | I20: 2 | J20: =C20*(F20+G20)*I20 -> 203.125
G22: TOTAL | I22: =SUM(I11:I18) -> 4.55
J29: =SUM(J11:J20) -> 1382.8125
A30: Confeccionado por:
A31: Nombre y Apellidos:
A32: Aprobado por:
A33: Nombre y Apellidos:

Sheet Gastos Financieros 
A1: MODELO 5 - DESGLOSE DE LOS GASTOS FINANCIEROS PROYECTADOS PARA EL AÑO POR CRÉDITOS BANCARIOS
A4: ORGANISMO:
A5: EMPRESA:
A6: Destino del Crédito | B6: Gastos financieros
B7: Intereses | C7: Comisiones Bancarias | D7: Total
A8: Pago de Préstamos (835) | D8: 0
A29: Total | B29: =B8+B18 -> 0 | C29: =C8+C18 -> 0 | D29: =D8+D18 -> 0
A30: Confeccionado por: (Nombre y Apellidos) | C30: Cargo:
A31: Aprobado por: (Nombre y Apellidos) | C31: Cargo:

Sheet Otros Gastos Directos 
A2: Otros Gastos Directos
A3: Concepto | B3: Total
G4: m2
A5: Depreciación | B5: =450.1/39968 -> 0.011261509 | C5: =450.1/39968.56 -> 0.011261351 | G5: ='Ficha de costo (Resumen)'!F41 -> 5.208
A6: Estimulacion xM2 Cristal (100 cup) | B6: 0
A7: Estimulacion xM2 Producto standar (1335cup) | B7: =1355*'Ficha de costo (Resumen)'!F41 -> 7056.84
A13: Total de Otros gastos directos | B13: =SUM(B5:B12) -> 7056.8513 | C13: =SUM(C5:C12) -> 0.011261351
